Workbook

Sheet Service Ticket (Original)
A6: Service Ticket (Original)
A8: Customer: | B8: HAROUGE | C8: Ticket NO: | E8: 1897
A9: Field Name: | B9: GHANI
A10: Well No: | B10: VVV08-11 | C10: MKN Supervisor: | E10: M. Gomoha , Abdsalam
A11: Rig Name: | B11: ADC#27 | C11: Start Job: | E11: 46207
A12: Mileage (Km): | B12: 450 | C12: End Job: | E12: 46220
A13: Base Location: | B13: Operational Base Coordinates: Awjilah (+29.107970, +21.376782)
A14: 7'' Combination For CSG Test & Cement Job
A15: Item no. | B15: Item Description | C15: Qty | D15: Unit | E15: Unit Cost | F15: Total Cost
A16: MKN-1801 | B16: Pick-up with tools traveling to wells, per KM. | C16: =B12*2 -> 900 | D16: km (Round Trip) | E16: 3.9 | F16: =C16*E16 -> 3510
A17: MKN-1804 | B17: Supervisor or Engineer, per day or fraction | C17: 4 | D17: Day | E17: 1050 | F17: =C17*E17 -> 4200
A18: MKN-1828 | B18: Retrievable Bridg Plug Size thru 7'': First Day | C18: 1 | D18: Day | E18: 1900 | F18: =C18*E18 -> 1900
A19: MKN-1829 | B19: Retrievable Bridg Plug Size thru 7'': After First Day | C19: 13 | D19: Day | E19: 800 | F19: =C19*E19 -> 10400
A20: MKN-1808 | B20: Packer Size thru 7'': First Day | C20: 1 | D20: Day | E20: 2200 | F20: =C20*E20 -> 2200
A21: MKN-1809 | B21: Packer Size thru 7'': After First Day | C21: 3 | D21: Day | E21: 800 | F21: =C21*E21 -> 2400
A22: MKN-1963 | B22: DESERT/MARINE Surchargeadd to all invoices | D22: 0.2 | E22: =SUM(F16:F21) -> 24610 | F22: =E22*0.2 -> 4922
B24: Discount 60% | E24: =E22+F22 -> 29532 | F24: =-(E24*0.6) -> -17719.2
A40: Total = | F40: =E24+F24 -> 11812.8
A44: Customer or his agent | C44: MAKAMAN LIBYA
A49: Representative Signature | C49: Representative Signature

Sheet Service Ticket (Copy)
A6: Service Ticket (Copy)
A8: Customer: | B8: ='Service Ticket (Original)'!B8 -> HAROUGE | C8: Ticket NO: | E8: ='Service Ticket (Original)'!E8 -> 1897
A9: Field Name: | B9: ='Service Ticket (Original)'!B9 -> GHANI
A10: Well No: | B10: ='Service Ticket (Original)'!B10 -> VVV08-11 | C10: MKN Supervisor: | E10: ='Service Ticket (Original)'!E10 -> M. Gomoha , Abdsalam
A11: Rig Name: | B11: ='Service Ticket (Original)'!B11 -> ADC#27 | C11: Start Job: | E11: ='Service Ticket (Original)'!E11 -> 46207
A12: Mileage (Km): | B12: ='Service Ticket (Original)'!B12 -> 450 | C12: End Job: | E12: ='Service Ticket (Original)'!E12 -> 46220
A13: Base Location: | B13: ='Service Ticket (Original)'!B13 -> Operational Base Coordinates: Awjilah (+29.107970, +21.376782)
A14: ='Service Ticket (Original)'!A14 -> 7'' Combination For CSG Test & Cement Job
A15: Item no. | B15: Item Description | C15: Qty | D15: Unit | E15: Unit Cost | F15: Total Cost
A16: ='Service Ticket (Original)'!A16 -> MKN-1801 | B16: ='Service Ticket (Original)'!B16 -> Pick-up with tools traveling to wells, per KM. | C16: ='Service Ticket (Original)'!C16 -> 900 | D16: ='Service Ticket (Original)'!D16 -> km (Round Trip) | E16: ='Service Ticket (Original)'!E16 -> 3.9 | F16: ='Service Ticket (Original)'!F16 -> 3510
A17: ='Service Ticket (Original)'!A17 -> MKN-1804 | B17: ='Service Ticket (Original)'!B17 -> Supervisor or Engineer, per day or fraction | C17: ='Service Ticket (Original)'!C17 -> 4 | D17: ='Service Ticket (Original)'!D17 -> Day | E17: ='Service Ticket (Original)'!E17 -> 1050 | F17: ='Service Ticket (Original)'!F17 -> 4200
A18: ='Service Ticket (Original)'!A18 -> MKN-1828 | B18: ='Service Ticket (Original)'!B18 -> Retrievable Bridg Plug Size thru 7'': First Day | C18: ='Service Ticket (Original)'!C18 -> 1 | D18: ='Service Ticket (Original)'!D18 -> Day | E18: ='Service Ticket (Original)'!E18 -> 1900 | F18: ='Service Ticket (Original)'!F18 -> 1900
A19: ='Service Ticket (Original)'!A19 -> MKN-1829 | B19: ='Service Ticket (Original)'!B19 -> Retrievable Bridg Plug Size thru 7'': After First Day | C19: ='Service Ticket (Original)'!C19 -> 13 | D19: ='Service Ticket (Original)'!D19 -> Day | E19: ='Service Ticket (Original)'!E19 -> 800 | F19: ='Service Ticket (Original)'!F19 -> 10400
A20: ='Service Ticket (Original)'!A20 -> MKN-1808 | B20: ='Service Ticket (Original)'!B20 -> Packer Size thru 7'': First Day | C20: ='Service Ticket (Original)'!C20 -> 1 | D20: ='Service Ticket (Original)'!D20 -> Day | E20: ='Service Ticket (Original)'!E20 -> 2200 | F20: ='Service Ticket (Original)'!F20 -> 2200
A21: ='Service Ticket (Original)'!A21 -> MKN-1809 | B21: ='Service Ticket (Original)'!B21 -> Packer Size thru 7'': After First Day | C21: ='Service Ticket (Original)'!C21 -> 3 | D21: ='Service Ticket (Original)'!D21 -> Day | E21: ='Service Ticket (Original)'!E21 -> 800 | F21: ='Service Ticket (Original)'!F21 -> 2400
A22: ='Service Ticket (Original)'!A22 -> MKN-1963 | B22: ='Service Ticket (Original)'!B22 -> DESERT/MARINE Surchargeadd to all invoices | C22: ='Service Ticket (Original)'!C22 -> 0 | D22: ='Service Ticket (Original)'!D22 -> 0.2 | E22: ='Service Ticket (Original)'!E22 -> 24610 | F22: ='Service Ticket (Original)'!F22 -> 4922
A23: ='Service Ticket (Original)'!A23 -> 0 | B23: ='Service Ticket (Original)'!B23 -> 0 | C23: ='Service Ticket (Original)'!C23 -> 0 | D23: ='Service Ticket (Original)'!D23 -> 0 | E23: ='Service Ticket (Original)'!E23 -> 0 | F23: ='Service Ticket (Original)'!F23 -> 0
A24: ='Service Ticket (Original)'!A24 -> 0 | B24: ='Service Ticket (Original)'!B24 -> Discount 60% | C24: ='Service Ticket (Original)'!C24 -> 0 | D24: ='Service Ticket (Original)'!D24 -> 0 | E24: ='Service Ticket (Original)'!E24 -> 29532 | F24: ='Service Ticket (Original)'!F24 -> -17719.2
A25: ='Service Ticket (Original)'!A25 -> 0 | B25: ='Service Ticket (Original)'!B25 -> 0 | C25: ='Service Ticket (Original)'!C25 -> 0 | D25: ='Service Ticket (Original)'!D25 -> 0 | E25: ='Service Ticket (Original)'!E25 -> 0 | F25: ='Service Ticket (Original)'!F25 -> 0
A26: ='Service Ticket (Original)'!A26 -> 0 | B26: ='Service Ticket (Original)'!B26 -> 0 | C26: ='Service Ticket (Original)'!C26 -> 0 | D26: ='Service Ticket (Original)'!D26 -> 0 | E26: ='Service Ticket (Original)'!E26 -> 0 | F26: ='Service Ticket (Original)'!F26 -> 0
A27: ='Service Ticket (Original)'!A27 -> 0 | B27: ='Service Ticket (Original)'!B27 -> 0 | C27: ='Service Ticket (Original)'!C27 -> 0 | D27: ='Service Ticket (Original)'!D27 -> 0 | E27: ='Service Ticket (Original)'!E27 -> 0 | F27: ='Service Ticket (Original)'!F27 -> 0
... A39: ='Service Ticket (Original)'!A39 -> 0 | B39: ='Service Ticket (Original)'!B39 -> 0 | C39: ='Service Ticket (Original)'!C39 -> 0 | D39: ='Service Ticket (Original)'!D39 -> 0 | E39: ='Service Ticket (Original)'!E39 -> 0 | F39: ='Service Ticket (Original)'!F39 -> 0
A40: ='Service Ticket (Original)'!A40 -> Total = | F40: ='Service Ticket (Original)'!F40 -> 11812.8
A44: Customer or his agent | C44: MAKAMAN LIBYA
A49: Representative Signature | C49: Representative Signature

Sheet Job Log (Original)
A6: Job Log (Original) | H6: ='Service Ticket (Original)'!E8 -> 1897
F7: Ticket No:
A10: Customer: | B10: ='Service Ticket (Original)'!B8 -> HAROUGE | E10: Date: | F10: ='Service Ticket (Original)'!E12 -> 46220
A12: Field: | B12: ='Service Ticket (Original)'!B9 -> GHANI | E12: Job Type: | F12: ='Service Ticket (Original)'!A14 -> 7'' Combination For CSG Test & Cement Job
A14: Well No: | B14: ='Service Ticket (Original)'!B10 -> VVV08-11 | E14: Customer Rep. | F14: Workover Office
A16: Job Supervisor: | B16: ='Service Ticket (Original)'!E10 -> M. Gomoha , Abdsalam | E16: Rig Name: | F16: ='Service Ticket (Original)'!B11 -> ADC#27
A17: Start Job | D17: End Job | F17: Arrived To Location
A18: ='Service Ticket (Original)'!E11 -> 46207 | D18: ='Service Ticket (Original)'!E12 -> 46220 | F18: ='Service Ticket (Original)'!E11 -> 46207
A19: Date | B19: Time | C19: Pressure | D19: Total | E19: Details of the Job
A20: =A18 -> 46207 | B20: 0.47916667 | C20: - | D20: - | E20: M/Up 7''( RBP & PKR) & RIH
A21: 46208 | B21: 0.3125 | C21: - | D21: - | E21: Set 7'' RBP@5250ft,Set 7'' PKR @5200ft, P/T 500psi BTW..Good
A22: - | B22: 0.375 | C22: - | D22: - | E22: Set 7'' PKR@(5015)ft , Injectivity Test
A23: - | B23: 0.39583333 | C23: - | D23: - | E23: POOH with 7" PKR & Overshot.
A24: - | B24: - | C24: - | D24: - | E24: -
A25: - | B25: - | C25: - | D25: - | E25: Cement Job Operation.
A26: - | B26: - | C26: - | D26: - | E26: -
A27: - | B27: - | C27: - | D27: - | E27: -
A28: - | B28: - | C28: - | D28: - | E28: -
A29: 46216 | B29: 0.33333333 | C29: - | D29: - | E29: RIH 7'' PKR ,
A30: - | B30: 0.54166667 | C30: - | D30: - | E30: Set 7'' PKR @ 5008ft, P/T Good Test
A31: - | B31: 0.58333333 | C31: - | D31: - | E31: Unset 7'' PKT & POOH .
A32: 46217 | B32: - | C32: - | D32: - | E32: -
A33: - | B33: 0.29166667 | C33: - | D33: - | E33: 7'' PKR On Surface
A34: - | B34: - | C34: - | D34: - | E34: -
A35: - | B35: - | C35: - | D35: - | E35: -
A36: 46219 | B36: - | C36: - | D36: - | E36: -
A37: - | B37: 0.29166667 | C37: - | D37: - | E37: RIH 7" Overshot
A38: - | B38: 0.64583333 | C38: - | D38: - | E38: Unset 7" RBP & POOH
A39: - | B39: - | C39: - | D39: - | E39: -
A40: 46220 | B40: 0.39583333 | C40: - | D40: - | E40: RBP on surface
A41: - | B41: - | C41: - | D41: - | E41: -
A42: - | B42: - | C42: - | D42: - | E42: -
A43: - | B43: - | C43: - | D43: - | E43: -
A44: =D18 -> 46220 | B44: - | C44: - | D44: - | E44: -
A45: Customer or his agent | E45: MAKAMAN Libya
A48: Representative Signature | E48: Representative Signature

Sheet Job Log (Copy)
A6: Job Log (Copy) | H6: ='Service Ticket (Original)'!E8 -> 1897
F7: Ticket No:
A10: Customer: | B10: ='Service Ticket (Original)'!B8 -> HAROUGE | E10: Date: | F10: ='Service Ticket (Original)'!E12 -> 46220
A12: Field: | B12: ='Service Ticket (Original)'!B9 -> GHANI | E12: Job Type: | F12: ='Service Ticket (Original)'!A14 -> 7'' Combination For CSG Test & Cement Job
A14: Well No: | B14: ='Service Ticket (Original)'!B10 -> VVV08-11 | E14: Customer Rep. | F14: Workover Office
A16: Job Supervisor: | B16: ='Service Ticket (Original)'!E10 -> M. Gomoha , Abdsalam | E16: Rig Name: | F16: ='Service Ticket (Original)'!B11 -> ADC#27
A17: Start Job | D17: End Job | F17: Arrived To Location
A18: ='Service Ticket (Original)'!E11 -> 46207 | D18: ='Service Ticket (Original)'!E12 -> 46220 | F18: ='Service Ticket (Original)'!E11 -> 46207
A19: Date | B19: Time | C19: Pressure | D19: Total | E19: Details of the Job
A20: ='Job Log (Original)'!A20 -> 46207 | B20: ='Job Log (Original)'!B20 -> 0.47916667 | C20: ='Job Log (Original)'!C20 -> - | D20: ='Job Log (Original)'!D20 -> - | E20: ='Job Log (Original)'!E20 -> M/Up 7''( RBP & PKR) & RIH
A21: ='Job Log (Original)'!A21 -> 46208 | B21: ='Job Log (Original)'!B21 -> 0.3125 | C21: ='Job Log (Original)'!C21 -> - | D21: ='Job Log (Original)'!D21 -> - | E21: ='Job Log (Original)'!E21 -> Set 7'' RBP@5250ft,Set 7'' PKR @5200ft, P/T 500psi BTW..Good
A22: ='Job Log (Original)'!A22 -> - | B22: ='Job Log (Original)'!B22 -> 0.375 | C22: ='Job Log (Original)'!C22 -> - | D22: ='Job Log (Original)'!D22 -> - | E22: ='Job Log (Original)'!E22 -> Set 7'' PKR@(5015)ft , Injectivity Test
A23: ='Job Log (Original)'!A23 -> - | B23: ='Job Log (Original)'!B23 -> 0.39583333 | C23: ='Job Log (Original)'!C23 -> - | D23: ='Job Log (Original)'!D23 -> - | E23: ='Job Log (Original)'!E23 -> POOH with 7" PKR & Overshot.
A24: ='Job Log (Original)'!A24 -> - | B24: ='Job Log (Original)'!B24 -> - | C24: ='Job Log (Original)'!C24 -> - | D24: ='Job Log (Original)'!D24 -> - | E24: ='Job Log (Original)'!E24 -> -
A25: ='Job Log (Original)'!A25 -> - | B25: ='Job Log (Original)'!B25 -> - | C25: ='Job Log (Original)'!C25 -> - | D25: ='Job Log (Original)'!D25 -> - | E25: ='Job Log (Original)'!E25 -> Cement Job Operation.
A26: ='Job Log (Original)'!A26 -> - | B26: ='Job Log (Original)'!B26 -> - | C26: ='Job Log (Original)'!C26 -> - | D26: ='Job Log (Original)'!D26 -> - | E26: ='Job Log (Original)'!E26 -> -
A27: ='Job Log (Original)'!A27 -> - | B27: ='Job Log (Original)'!B27 -> - | C27: ='Job Log (Original)'!C27 -> - | D27: ='Job Log (Original)'!D27 -> - | E27: ='Job Log (Original)'!E27 -> -
A28: ='Job Log (Original)'!A28 -> - | B28: ='Job Log (Original)'!B28 -> - | C28: ='Job Log (Original)'!C28 -> - | D28: ='Job Log (Original)'!D28 -> - | E28: ='Job Log (Original)'!E28 -> -
A29: ='Job Log (Original)'!A29 -> 46216 | B29: ='Job Log (Original)'!B29 -> 0.33333333 | C29: ='Job Log (Original)'!C29 -> - | D29: ='Job Log (Original)'!D29 -> - | E29: ='Job Log (Original)'!E29 -> RIH 7'' PKR ,
A30: ='Job Log (Original)'!A30 -> - | B30: ='Job Log (Original)'!B30 -> 0.54166667 | C30: ='Job Log (Original)'!C30 -> - | D30: ='Job Log (Original)'!D30 -> - | E30: ='Job Log (Original)'!E30 -> Set 7'' PKR @ 5008ft, P/T Good Test
A31: ='Job Log (Original)'!A31 -> - | B31: ='Job Log (Original)'!B31 -> 0.58333333 | C31: ='Job Log (Original)'!C31 -> - | D31: ='Job Log (Original)'!D31 -> - | E31: ='Job Log (Original)'!E31 -> Unset 7'' PKT & POOH .
... A44: ='Job Log (Original)'!A44 -> 46220 | B44: ='Job Log (Original)'!B44 -> - | C44: ='Job Log (Original)'!C44 -> - | D44: ='Job Log (Original)'!D44 -> - | E44: ='Job Log (Original)'!E44 -> -
A45: Customer or his agent | E45: MAKAMAN Libya
A48: Representative Signature | E48: Representative Signature

Sheet WAHA 1 Price List
A1: MAKAMAN LIBYA COMPANY For Waha
A2: Official Price List
A3: Oil Service Incorporated — Tools & Testing / Special Tools Service · All prices in USD ($) · Rates per unit as noted
A4: Client: | D4: Date:
A6: A. TRANSPORTATION & PERSONNEL | F6: ← Contents
A8: Transportation & Personnel — Daily Rates
A9: Item Code | B9: Description | C9: Unit | D9: Price
A10: ='[1]1'!A7 -> MKN-001 | B10: ='[1]1'!B7 -> Pick-up with tools traveling to wells, per KM. | C10: per KM | D10: ='[1]1'!C7 -> 3
A11: ='[1]1'!A8 -> MKN-002 | B11: ='[1]1'!B8 -> Tool operator, per day or fraction | C11: per day | D11: ='[1]1'!C8 -> 950
A12: ='[1]1'!A9 -> MKN-003 | B12: ='[1]1'!B9 -> Assistant Tool Operator, per day or fraction | C12: per day | D12: ='[1]1'!C9 -> 800
A13: ='[1]1'!A10 -> MKN-004 | B13: ='[1]1'!B10 -> Supervisor or Engineer, per day or fraction | C13: per day | D13: ='[1]1'!C10 -> 1050
A14: ='[1]1'!A11 -> MKN-005 | B14: ='[1]1'!B11 -> Helper, per day or fraction | C14: per day | D14: ='[1]1'!C11 -> 500
A16: B. RETRIEVABLE PACKERS, BRIDGE PLUGS & SETTING TOOLS | F16: ← Contents
A18: Retrievable Test, Treat & Squeeze Packer
A19: Item Code | B19: Description | C19: Unit | D19: First Day | E19: Add. Day
A20: ='[1]1'!A13 -> MKN-006 | B20: Size thru 7" | C20: per day | D20: ='[1]1'!C13 -> 2200 | E20: ='[1]1'!C14 -> 850
A21: ='[1]1'!A15 -> MKN-008 | B21: Size thru 9 5/8" | C21: per day | D21: ='[1]1'!C15 -> 2900 | E21: ='[1]1'!C16 -> 950
A22: ='[1]1'!A17 -> MKN-010 | B22: Size 13 3/8" | C22: per day | D22: ='[1]1'!C17 -> 5000 | E22: ='[1]1'!C18 -> 1100
A24: Retrievable Bridge Plug — Run Separately
A25: Item Code | B25: Description | C25: Unit | D25: First Day | E25: Add. Day
A26: ='[1]1'!A21 -> MKN-012 | B26: Size thru 7" | C26: per day | D26: ='[1]1'!C21 -> 2200 | E26: ='[1]1'!C22 -> 850
A27: ='[1]1'!A23 -> MKN-014 | B27: Size thru 9 5/8" | C27: per day | D27: ='[1]1'!C23 -> 2900 | E27: ='[1]1'!C24 -> 950
A28: ='[1]1'!A25 -> MKN-016 | B28: Size 13 3/8" | C28: per day | D28: ='[1]1'!C25 -> 5000 | E28: ='[1]1'!C26 -> 1100
A30: Retrievable Bridge Plug — Run With Another MAKAMAN Packer
A31: Item Code | B31: Description | C31: Unit | D31: First Day | E31: Add. Day
A32: ='[1]1'!A29 -> MKN-018 | B32: Size thru 7" | C32: per day | D32: ='[1]1'!C29 -> 1900 | E32: ='[1]1'!C30 -> 800
A33: ='[1]1'!A31 -> MKN-020 | B33: Size thru 9 5/8" | C33: per day | D33: ='[1]1'!C31 -> 2700 | E33: ='[1]1'!C32 -> 1000
A34: ='[1]1'!A33 -> MKN-022 | B34: Size 13 3/8" | C34: per day | D34: ='[1]1'!C33 -> 4500 | E34: ='[1]1'!C34 -> 1200
A36: Setting Tools & Accessories
A37: Item Code | B37: Description | C37: Unit | D37: Price
A38: ='[1]1'!A35 -> MKN-024 | B38: ='[1]1'!B35 -> Crossover subs, Per sub, Per job. | C38: per job | D38: ='[1]1'!C35 -> 50
A39: ='[1]2'!A5 -> MKN-025 | B39: =TRIM('[1]2'!B5) -> MECHANICAL SETTING TOOL, per run | C39: per run | D39: ='[1]2'!C5 -> 1850
A40: ='[1]2'!A6 -> MKN-026 | B40: =TRIM('[1]2'!B6) -> Wire line kit for cement Retainer/Bridge plug, Per run | C40: per run | D40: ='[1]2'!C6 -> 300
A41: ='[1]2'!A7 -> MKN-027 | B41: =TRIM('[1]2'!B7) -> Tubing Stinger Coupling/ (SSA), Per job | C41: per job | D41: ='[1]2'!C7 -> 350
A42: ='[1]2'!A8 -> MKN-028 | B42: =TRIM('[1]2'!B8) -> Tubing Centralizer ,Per job | C42: per job | D42: ='[1]2'!C8 -> 300
A44: C. DRILLABLE CEMENT RETAINERS & BRIDGE PLUGS — SALES | F44: ← Contents
A46: Drillable Cement Retainers & Drillable Bridge Plug Packer — by Casing OD (Sale)
A47: Item Code | B47: Description | C47: Unit | D47: Price
A48: ='[1]2'!A14 -> MKN-029 | B48: ="Casing OD "&'[1]2'!B14 -> Casing OD 4 1/2" | C48: per unit | D48: ='[1]2'!C14 -> 3000
A49: ='[1]2'!A15 -> MKN-030 | B49: ="Casing OD "&'[1]2'!B15 -> Casing OD 5" | C49: per unit | D49: ='[1]2'!C15 -> 3200
...

Sheet WAHA 2 Price List
A1: MAKAMAN LIBYA COMPANY For Waha
A2: Official Price List
A3: All prices in US Dollars (US$). Terms and conditions of Makaman Libya Company apply.
A4: Client: | D4: Date: | E4: =TODAY() -> 46251
A6: A. FISHING & SPECIAL TOOLS | F6: ← Contents
A8: Fishing Jar & Bumper Sub Redress Charges
A9: Item Code | B9: Description | C9: Unit | D9: Price (US$)
A10: ='[2]1'!A5 -> MKN 100-203 | B10: ='[2]1'!B5 -> Redress charge for fishing jar thru 6 ½” OD | C10: ='[2]1'!C5 -> Per run | D10: ='[2]1'!D5 -> 800
A11: ='[2]1'!A6 -> MKN 100-204 | B11: ='[2]1'!B6 -> Redress charge for fishing jar thru 8 ¾” OD | C11: ='[2]1'!C6 -> Per run | D11: ='[2]1'!D6 -> 900
A12: ='[2]1'!A7 -> MKN 100-205 | B12: ='[2]1'!B7 -> Redress charge for bumper sub thru 6 ¼” OD | C12: ='[2]1'!C7 -> Per run | D12: ='[2]1'!D7 -> 600
A13: ='[2]1'!A8 -> MKN 100-206 | B13: ='[2]1'!B8 -> Redress charge for bumper sub thru 8 ¾” OD | C13: ='[2]1'!C8 -> Per run | D13: ='[2]1'!D8 -> 700
A15: Impression Block, Junk Basket & Washover Pipe Redress
A16: Item Code | B16: Description | C16: Unit | D16: Price (US$)
A17: ='[2]1'!A12 -> MKN 100-207 | B17: ='[2]1'!B12 -> Refill impression block thru 8” OD | C17: ='[2]1'!C12 -> Per run | D17: ='[2]1'!D12 -> 910
A18: ='[2]1'!A13 -> MKN 100-208 | B18: ='[2]1'!B13 -> Refill impression block thru 13 3/8” OD | C18: ='[2]1'!C13 -> Per run | D18: ='[2]1'!D13 -> 990
A19: ='[2]1'!A14 -> MKN 100-209 | B19: ='[2]1'!B14 -> Redress junk basket with tungsten carbide thru 8 ¾” OD | C19: ='[2]1'!C14 -> Per run | D19: ='[2]1'!D14 -> 760
A20: ='[2]1'!A15 -> MKN 100-210 | B20: ='[2]1'!B15 -> Redress junk basket with tungsten carbide thru 13 3/8” OD | C20: ='[2]1'!C15 -> Per run | D20: ='[2]1'!D15 -> 885
A21: ='[2]1'!A16 -> MKN 100-211 | B21: ='[2]1'!B16 -> Redress charge for washover pipe all sizes | C21: ='[2]1'!C16 -> ….. | D21: ='[2]1'!D16 -> 2750
A23: Mills & Mill Refills
A24: Item Code | B24: Description | C24: First Day (US$) | D24: Additional Day (US$)
A25: ='[2]1'!A21 -> MKN 100-212 | B25: ='[2]1'!B21 -> Skirted mill thru 8 ¾” OD | C25: ='[2]1'!D21 -> 1350 | D25: ='[2]1'!E21 -> 500
A26: ='[2]1'!A22 -> MKN 100-213 | B26: ='[2]1'!B22 -> Skirted mill thru 13 3/8” OD | C26: ='[2]1'!D22 -> 1550 | D26: ='[2]1'!E22 -> 600
A27: ='[2]1'!A23 -> MKN 100-214 | B27: ='[2]1'!B23 -> Refill washover pipe dressed with crushed carbide for skirted mill all | C27: ='[2]1'!D23 -> 1250
A28: ='[2]1'!A24 -> MKN 100-215 | B28: ='[2]1'!B24 -> Refill junk mill with crushed carbide for skirted mill all sizes | C28: ='[2]1'!D24 -> 1350
A29: ='[2]1'!A25 -> MKN 100-216 | B29: ='[2]1'!B25 -> Flat bottom Mill all size | C29: ='[2]1'!D25 -> 385
A30: ='[2]1'!A26 -> MKN 100-217 | B30: ='[2]1'!B26 -> Refill flat bottom mill all size | C30: ='[2]1'!D26 -> 575
A32: Cable Spears, Overshot Redress Kits & Tool Inspection
A33: Item Code | B33: Description | C33: Unit | D33: Price (US$)
A34: ='[2]1'!A30 -> MKN 100-218 | B34: ='[2]1'!B30 -> Cable spear thru 8 ¾” OD | C34: ='[2]1'!C30 -> Per run | D34: ='[2]1'!D30 -> 1650
A35: ='[2]1'!A31 -> MKN 100-219 | B35: ='[2]1'!B31 -> Cable spear thru 13 3/8” OD | C35: ='[2]1'!C31 -> Per run | D35: ='[2]1'!D31 -> 1850
A36: ='[2]1'!A32 -> MKN 100-220 | B36: ='[2]1'!B32 -> Redress kit overshot wide range for all sizes | D36: ='[2]1'!D32 -> 2850
A37: ='[2]1'!A33 -> MKN 100-221 | B37: ='[2]1'!B33 -> Inspection charge for all tools as per third party company invoice | C37: ='[2]1'!C33 -> Per tool
A39: Bailers, Sand Pumps, Clamps, Elevators & Workshop Labour
A40: Item Code | B40: Description | C40: Unit | D40: First Day (US$) | E40: Additional Day (US$)
A41: ='[2]2'!A6 -> MKN 100-222 | B41: ='[2]2'!B6 -> Bailer or sand pump all sizes | C41: ='[2]2'!C6 -> Per day | D41: ='[2]2'!D6 -> 950 | E41: ='[2]2'!E6 -> 385
A42: ='[2]2'!A7 -> MKN 100-223 | B42: ='[2]2'!B7 -> Bailer or sand pump redress charge will be 50% from | C42: ='[2]2'!C7 -> 50% F.Day | D42: ='[2]2'!D7 -> 475
A43: ='[2]2'!A8 -> MKN 100-224 | B43: ='[2]2'!B8 -> Safety clamps all sizes | C43: ='[2]2'!C8 -> Per run | D43: ='[2]2'!D8 -> 40
A44: ='[2]2'!A9 -> MKN 100-225 | B44: ='[2]2'!B9 -> Elevators charge all sizes | C44: ='[2]2'!C9 -> Per day | D44: ='[2]2'!D9 -> 65
A45: ='[2]2'!A10 -> MKN 100-226 | B45: ='[2]2'!B10 -> Safety joint charge all sizes | C45: ='[2]2'!C10 -> Per run | D45: ='[2]2'!D10 -> 1850
A46: ='[2]2'!A11 -> MKN 100-227 | B46: ='[2]2'!B11 -> Workshop redressing technician rate | C46: ='[2]2'!C11 -> Per day | D46: ='[2]2'!D11 -> 750
...

Sheet AGOCO Price List
A1: MAKAMAN LIBYA COMPANY For AGOCO
A2: Official Price List
A3: All prices in USD. Prices exclusive of taxes and duties. Terms and conditions per master service agreement.
A4: Client: | D4: Date:
A6: A. FISHING & SPECIAL TOOLS | F6: ← Contents
A8: Personnel & Transportation — Daily Rates
A9: Item Code | B9: Description | C9: Unit | D9: Price (USD)
A10: ='[3]5'!A7 -> MKN 100-0205 | B10: ='[3]5'!B7 -> Fishing Tool Supervisor | C10: ='[3]5'!C7 -> $/day | D10: ='[3]5'!D7 -> 1200
A11: ='[3]5'!A8 -> MKN 100-0210 | B11: ='[3]5'!B8 -> Tools pick up | C11: ='[3]5'!C8 -> $/km | D11: ='[3]5'!D8 -> 2
A12: ='[3]5'!A9 -> MKN 100-0215 | B12: ='[3]5'!B9 -> Truck | C12: ='[3]5'!C9 -> $/km | D12: ='[3]5'!D9 -> 3
A14: Baskets — Junk
A15: Item Code | B15: Description | C15: Unit | D15: First Day | E15: Additional Day
A16: ='[3]6'!A10 -> MKN 100-001 | B16: ='[3]6'!B10 -> Thru 3-3/4"OD | C16: ='[3]6'!C10 -> $/day | D16: ='[3]6'!D10 -> 270 | E16: ='[3]6'!E10 -> 25
A17: ='[3]6'!A11 -> MKN 100-002 | B17: ='[3]6'!B11 -> Thru 4-1/4"OD | C17: ='[3]6'!C11 -> $/day | D17: ='[3]6'!D11 -> 280 | E17: ='[3]6'!E11 -> 25
A18: ='[3]6'!A12 -> MKN 100-003 | B18: ='[3]6'!B12 -> Thru 4-3/4" OD | C18: ='[3]6'!C12 -> $/day | D18: ='[3]6'!D12 -> 360 | E18: ='[3]6'!E12 -> 35
A19: ='[3]6'!A13 -> MKN 100-004 | B19: ='[3]6'!B13 -> Thru 5-3/4" OD | C19: ='[3]6'!C13 -> $/day | D19: ='[3]6'!D13 -> 400 | E19: ='[3]6'!E13 -> 40
A20: ='[3]6'!A14 -> MKN 100-005 | B20: ='[3]6'!B14 -> Thru 6-1/8"OD | C20: ='[3]6'!C14 -> $/day | D20: ='[3]6'!D14 -> 420 | E20: ='[3]6'!E14 -> 40
A21: ='[3]6'!A15 -> MKN 100-006 | B21: ='[3]6'!B15 -> Thru 6-3/4"OD | C21: ='[3]6'!C15 -> $/day | D21: ='[3]6'!D15 -> 470 | E21: ='[3]6'!E15 -> 45
A22: ='[3]6'!A16 -> MKN 100-007 | B22: ='[3]6'!B16 -> Thru 7-3/4"OD | C22: ='[3]6'!C16 -> $/day | D22: ='[3]6'!D16 -> 490 | E22: ='[3]6'!E16 -> 50
A23: ='[3]6'!A17 -> MKN 100-008 | B23: ='[3]6'!B17 -> Thru 9-3/4"OD | C23: ='[3]6'!C17 -> $/day | D23: ='[3]6'!D17 -> 650 | E23: ='[3]6'!E17 -> 65
A24: ='[3]6'!A18 -> MKN 100-009 | B24: ='[3]6'!B18 -> Thru 10-3/4"OD | C24: ='[3]6'!C18 -> $/day | D24: ='[3]6'!D18 -> 800 | E24: ='[3]6'!E18 -> 85
A25: ='[3]6'!A19 -> MKN 100-011 | B25: ='[3]6'!B19 -> Thru 12-1/4"OD | C25: ='[3]6'!C19 -> $/day | D25: ='[3]6'!D19 -> 1050 | E25: ='[3]6'!E19 -> 100
A27: Baskets — Reverse Circulating Jet, Tungsten Carbide Dressed
A28: Item Code | B28: Description | C28: Unit | D28: Price (USD)
A29: ='[3]7'!A8 -> MKN 100-012 | B29: ='[3]7'!B8 -> Thru 8-3/4"OD | C29: ='[3]7'!C8 -> Price/Largest OD in/Run | D29: ='[3]7'!D8 -> 280
A30: ='[3]7'!A9 -> MKN 100-013 | B30: ='[3]7'!B9 -> Thru 17-1/2"OD | C30: ='[3]7'!C9 -> Price/Largest OD in/Run | D30: ='[3]7'!D9 -> 300
A32: Baskets — Junk (Poor Boy, Drag Tooth)
A33: Item Code | B33: Description | C33: Unit | D33: Price (USD)
A34: ='[3]7'!A11 -> MKN 100-014 | B34: ='[3]7'!B11 -> Thru 7" OD | C34: ='[3]7'!C11 -> Per Run | D34: ='[3]7'!D11 -> 510
A35: ='[3]7'!A12 -> MKN 100-015 | B35: ='[3]7'!B12 -> Thru 10-3/4"OD | C35: ='[3]7'!C12 -> Per Run | D35: ='[3]7'!D12 -> 820
A36: ='[3]7'!A13 -> MKN 100-016 | B36: ='[3]7'!B13 -> Thru 13-3/8"OD | C36: ='[3]7'!C13 -> Per Run | D36: ='[3]7'!D13 -> 1030
A38: Impression Blocks
A39: Item Code | B39: Description | C39: Unit | D39: Price (USD)
A40: ='[3]8'!A8 -> MKN 100-017 | B40: ='[3]8'!B8 -> 8" OD & Smaller | C40: ='[3]8'!C8 -> Price/Largest OD in/JOB | D40: ='[3]8'!D8 -> 85
A41: ='[3]8'!A9 -> MKN 100-018 | B41: ='[3]8'!B9 -> Over 8" | C41: ='[3]8'!C9 -> Price/Largest OD in/JOB | D41: ='[3]8'!D9 -> 100
A43: Boxes — Metal
A44: Item Code | B44: Description | C44: Unit | D44: Price (USD)
A45: ='[3]8'!A11 -> MKN 100-019 | B45: ='[3]8'!B11 -> ALL Sizes | C45: ='[3]8'!C11 -> Per Job | D45: ='[3]8'!D11 -> 95
A47: Washpipe Spears — Triple Connection or Canfield
A48: Item Code | B48: Description | C48: Unit | D48: First Day | E48: Additional Day
...

Sheet HOO Price List
A1: MAKAMAN LIBYA COMPANY For Harouge Oil Operations
A2: Official Price List — Tools and Testing
A3: All prices in USD ($). Prices subject to surcharges per Terms & Conditions. Quotation only — not a contract.
A4: Client: | D4: Date:
A6: A. TOOLS SERVICES | F6: ← Contents
A8: Transportation & Personnel
A9: Item Code | B9: Description | C9: Price
A10: ='[4]1'!A11 -> MKN-1801 | B10: ='[4]1'!B11 -> Pick-up with tools traveling to wells, per KM. | C10: ='[4]1'!C11 -> 3.9
A11: ='[4]1'!A12 -> MKN-1802 | B11: ='[4]1'!B12 -> Tool operator, per day or fraction | C11: ='[4]1'!C12 -> 950
A12: ='[4]1'!A13 -> MKN-1803 | B12: ='[4]1'!B13 -> Assistant Tool Operator, per day or fraction | C12: ='[4]1'!C13 -> 800
A13: ='[4]1'!A14 -> MKN-1804 | B13: ='[4]1'!B14 -> Supervisor or Engineer, per day or fraction | C13: ='[4]1'!C14 -> 1050
A14: ='[4]1'!A15 -> MKN-1805 | B14: ='[4]1'!B15 -> Helper, per day or fraction | C14: ='[4]1'!C15 -> 500
A15: ='[4]1'!A16 -> MKN-1806 | B15: ='[4]1'!B16 -> STAND-BY FRIST SIX HOURS after arriving on location | C15: ='[4]1'!C16 -> No charge
B16: ='[4]1'!B17 -> After the Frist Six 06) Hours, STAND-BY, PER HOUR OR FRACTION until job started per tool, until PERSONNEL CHARGES will be in addition. | C16: ='[4]1'!C17 -> 90
A17: ='[4]1'!A18 -> MKN-1807 | B17: ='[4]1'!B18 -> JOB CANCELITION When called to location and the job is not run, | C17: ='[4]1'!C18 -> 1800
A18: Job cancellation: when called to location and the job is not run due to circumstances beyond our control, personnel charges are in addition.
A20: Retrievable Test, Treat & Squeeze Packer — First 8 Hours or Fraction
A21: Item Code | B21: Description | C21: Price
A22: ='[4]1'!A26 -> MKN-1808 | B22: ='[4]1'!B26 -> "Size thru 7 | C22: ='[4]1'!C26 -> 2200
A23: ='[4]1'!A27 -> MKN-1809 | B23: ='[4]1'!B27 -> AFTER FIRST DAY size 7" | C23: ='[4]1'!C27 -> 800
A24: ='[4]1'!A28 -> MKN-1810 | B24: ='[4]1'!B28 -> "Size thru 95/8. | C24: ='[4]1'!C28 -> 2900
A25: ='[4]1'!A29 -> MKN-1811 | B25: ='[4]1'!B29 -> AFTER FIRST DAY size 9 5/8" | C25: ='[4]1'!C29 -> 950
A26: ='[4]1'!A30 -> MKN-1812 | B26: ='[4]1'!B30 -> "Size 13 3/8. | C26: ='[4]1'!C30 -> 5000
A27: ='[4]1'!A31 -> MKN-1813 | B27: ='[4]1'!B31 -> AFTER FIRST DAY size 13 3/8" | C27: ='[4]1'!C31 -> 1100
A28: ='[4]1'!A32 -> MKN-1814 | B28: ='[4]1'!B32 -> All sizes, above 15,000 ft. per 100 ft. or fraction add | C28: ='[4]1'!C32 -> 75
A29: ='[4]1'!A33 -> MKN-1815 | B29: ='[4]1'!B33 -> ADDITIONAL ZONE. Each ADDITIONAL ZONE on same run in well, any depth: | C29: ='[4]1'!C33 -> 800
A30: ='[4]1'!A36 -> MKN-1816 | B30: ='[4]1'!B36 -> Unsuccessful run. | C30: ='[4]1'!C36 -> 1100
A31: ='[4]1'!A37 -> MKN-1817 | B31: ='[4]1'!B37 -> Each Reset Packer For All Sizes | C31: ='[4]1'!C37 -> 200
A32: Price is determined by size and depth packer set. Job time begins when the tool starts in the well and ends when recovered. Additional zone charge applies when the tool is moved to another zone for any purpose (excludes looking for casing leaks).
A34: Retrievable Bridge Plug (run with another Makaman packer) — First 8 Hours or Fraction
A35: Item Code | B35: Description | C35: Price
A36: ='[4]2'!A10 -> MKN-1818 | B36: ='[4]2'!B10 -> Size thru 7" : first day | C36: ='[4]2'!C10 -> 2200
A37: ='[4]2'!A11 -> MKN-1819 | B37: ='[4]2'!B11 -> Size thru 7" : after first day | C37: ='[4]2'!C11 -> 850
A38: ='[4]2'!A12 -> MKN-1820 | B38: ='[4]2'!B12 -> Size thru 9 5/8" : first day | C38: ='[4]2'!C12 -> 2900
A39: ='[4]2'!A13 -> MKN-1821 | B39: ='[4]2'!B13 -> Size thru 9 5/8" : after first day | C39: ='[4]2'!C13 -> 950
A40: ='[4]2'!A14 -> MKN-1822 | B40: ='[4]2'!B14 -> Size 13 3/8" : first day | C40: ='[4]2'!C14 -> 5000
A41: ='[4]2'!A15 -> MKN-1823 | B41: ='[4]2'!B15 -> Size 13 3/8" : after first day | C41: ='[4]2'!C15 -> 1100
A42: ='[4]2'!A16 -> MKN-1824 | B42: ='[4]2'!B16 -> All sizes above 15,000 ft. per 100 ft. or fraction: add | C42: ='[4]2'!C16 -> 75
A43: ='[4]2'!A17 -> MKN-1825 | B43: ='[4]2'!B17 -> ADDITIONAL TIME. Each additional consecutive 8-hour or fraction | C43: ='[4]2'!C17 -> 1100
A44: ='[4]2'!A18 -> MKN-1826 | B44: ='[4]2'!B18 -> Frac sand (M.E.) 20–40 per pound | C44: ='[4]2'!C18 -> 3.6
...

Sheet SOC Price List
A1: MAKAMAN LIBYA COMPANY For Sirte Oil Company
A2: Official Price List
A3: Prepared for Sirte Oil Company · All prices in Libyan Dinar (LYD), excluding VAT unless stated
A4: Client: | D4: Date:
A6: A. FISHING & SPECIAL TOOLS
F7: ← Contents
A8: Fishing Services — Supervisor & Transport
A9: Item Code | B9: Description | C9: Unit | D9: Price (LYD)
A10: ='[5]6'!A5 -> MKN 100-0205 | B10: ='[5]6'!B5 -> Fishing Tool Supervisor | C10: ='[5]6'!C5 -> LYD / Day | D10: ='[5]6'!D5 -> 5000
A11: ='[5]6'!A6 -> MKN 100-0210 | B11: ='[5]6'!B6 -> Tools pick up | C11: ='[5]6'!C6 -> km | D11: ='[5]6'!D6 -> 5
A12: ='[5]6'!A7 -> MKN 100-0215 | B12: ='[5]6'!B7 -> Truck | C12: ='[5]6'!C7 -> km | D12: ='[5]6'!D7 -> 7
A14: Baskets — Junk
A15: Item Code | B15: Description | C15: Unit | D15: First Day (LYD) | E15: Add. Day (LYD)
A16: ='[5]6'!A12 -> MKN 100-001 | B16: ='[5]6'!B12 -> Thru 3-3/4"OD | C16: ='[5]6'!C12 -> Per Day | D16: ='[5]6'!D12 -> 1150 | E16: ='[5]6'!E12 -> 210
A17: ='[5]6'!A13 -> MKN 100-002 | B17: ='[5]6'!B13 -> Thru 4-1/4"OD | C17: ='[5]6'!C13 -> Per Day | D17: ='[5]6'!D13 -> 1250 | E17: ='[5]6'!E13 -> 210
A18: ='[5]6'!A14 -> MKN 100-003 | B18: ='[5]6'!B14 -> Thru 4-3/4" OD | C18: ='[5]6'!C14 -> Per Day | D18: ='[5]6'!D14 -> 1250 | E18: ='[5]6'!E14 -> 210
A19: ='[5]6'!A15 -> MKN 100-004 | B19: ='[5]6'!B15 -> Thru 5-3/4" OD | C19: ='[5]6'!C15 -> Per Day | D19: ='[5]6'!D15 -> 1410 | E19: ='[5]6'!E15 -> 230
A20: ='[5]6'!A16 -> MKN 100-005 | B20: ='[5]6'!B16 -> Thru 6-1/8"OD | C20: ='[5]6'!C16 -> Per Day | D20: ='[5]6'!D16 -> 1410 | E20: ='[5]6'!E16 -> 230
A21: ='[5]6'!A17 -> MKN 100-006 | B21: ='[5]6'!B17 -> Thru 6-3/4"OD | C21: ='[5]6'!C17 -> Per Day | D21: ='[5]6'!D17 -> 1410 | E21: ='[5]6'!E17 -> 230
A22: ='[5]6'!A18 -> MKN 100-007 | B22: ='[5]6'!B18 -> Thru 7-3/4"OD | C22: ='[5]6'!C18 -> Per Day | D22: ='[5]6'!D18 -> 1520 | E22: ='[5]6'!E18 -> 245
A23: ='[5]6'!A19 -> MKN 100-008 | B23: ='[5]6'!B19 -> Thru 9-3/4"OD | C23: ='[5]6'!C19 -> Per Day | D23: ='[5]6'!D19 -> 1610 | E23: ='[5]6'!E19 -> 310
A24: ='[5]6'!A20 -> MKN 100-009 | B24: ='[5]6'!B20 -> Thru 10-3/4"OD | C24: ='[5]6'!C20 -> Per Day | D24: ='[5]6'!D20 -> 1610 | E24: ='[5]6'!E20 -> 310
A25: ='[5]6'!A21 -> MKN 100-011 | B25: ='[5]6'!B21 -> Thru 12-1/4"OD | C25: ='[5]6'!C21 -> Per Day | D25: ='[5]6'!D21 -> 1610 | E25: ='[5]6'!E21 -> 310
A27: Reverse Circulating Jet — Tungsten Carbide Dressed Head
A28: Item Code | B28: Description | C28: Unit | D28: Price (LYD)
A29: ='[5]6'!A25 -> MKN 100-012 | B29: ='[5]6'!B25 -> Thru 8-3/4"OD | C29: ='[5]6'!C25 -> Price/Largest OD in/Run | D29: ='[5]6'!D25 -> 650
A30: ='[5]6'!A26 -> MKN 100-013 | B30: ='[5]6'!B26 -> Thru 17-1/2"OD | C30: ='[5]6'!C26 -> Price/Largest OD in/Run | D30: ='[5]6'!D26 -> 750
A32: Baskets — Junk (Poor Boy, Drag Tooth or Friction Type)
A33: Item Code | B33: Description | C33: Unit | D33: Price (LYD)
A34: ='[5]6'!A28 -> MKN 100-014 | B34: ='[5]6'!B28 -> Thru 7" OD | C34: ='[5]6'!C28 -> Per Run | D34: ='[5]6'!D28 -> 1600
A35: ='[5]6'!A29 -> MKN 100-015 | B35: ='[5]6'!B29 -> Thru 10-3/4"OD | C35: ='[5]6'!C29 -> Per Run | D35: ='[5]6'!D29 -> 3050
A36: ='[5]6'!A30 -> MKN 100-016 | B36: ='[5]6'!B30 -> Thru 13-3/8"OD | C36: ='[5]6'!C30 -> Per Run | D36: ='[5]6'!D30 -> 4100
A38: Impression Blocks
A39: Item Code | B39: Description | C39: Unit | D39: Price (LYD)
A40: ='[5]6'!A34 -> MKN 100-017 | B40: ='[5]6'!B34 -> 8" OD & Smaller | C40: ='[5]6'!C34 -> HRS | D40: ='[5]6'!D34 -> 3800
A41: ='[5]6'!A35 -> MKN 100-018 | B41: ='[5]6'!B35 -> Over 8" | C41: ='[5]6'!C35 -> HRS | D41: ='[5]6'!D35 -> 4100
A43: Boxes — Metal
A44: Item Code | B44: Description | C44: Unit | D44: Price (LYD)
A45: ='[5]6'!A37 -> MKN 100-019 | B45: ='[5]6'!B37 -> ALL Sizes | C45: ='[5]6'!C37 -> Per Job | D45: ='[5]6'!D37 -> 305
A47: Triple Connection or Canfield — Washpipe Pin
...

Sheet Zueitina Price List
A1: MAKAMAN LIBYA COMPANY For Zueitina Oil Company
A3: TRANSPORTATION & PERSONNEL
A4: Item Code | B4: Description | C4: Price
A5: MKN-0001 | B5: Pick-up with tools traveling to wells, per KM. | C5: 3.9
A6: MKN-0002 | B6: Tool operator, per day or fraction | C6: 950
A7: MKN-0003 | B7: Assistant Tool Operator, per day or fraction | C7: 800
A8: MKN-0004 | B8: Supervisor or Engineer, per day or fraction | C8: 1050
A9: MKN-0005 | B9: Helper, per day or fraction | C9: 500
A10: MKN-0006 | B10: STAND-BY FRIST SIX HOURS after arriving on location | C10: No charge
B11: After the Frist Six 06) Hours, STAND-BY, PER HOUR OR FRACTION until job started per tool, until PERSONNEL CHARGES will be in addition. | C11: 90
A12: MKN-0007 | B12: JOB CANCELITION When called to location and the job is not run, | C12: 1800
B13: due to circumstances beyond our control. PERSONNEL CHARGES are in addition.
A15: RETRIVEVABLE TEST, TREAT AND SQUEEZE PACKER.
A16: Price is determined by size and depth packer set. Time of job begins when tool starts in well and time end when recovered from well.
A17: FRIST-EIGHT (8) HOURS or Fraction
A19: Item Code | B19: Description | C19: Price
A20: MKN-0008 | B20: "Size thru 7 | C20: 2200
A21: MKN-0009 | B21: AFTER FIRST DAY size 7" | C21: 800
A22: MKN-0010 | B22: "Size thru 95/8. | C22: 2900
A23: MKN-0011 | B23: AFTER FIRST DAY size 9 5/8" | C23: 950
A24: MKN-0012 | B24: "Size 13 3/8. | C24: 5000
A25: MKN-0013 | B25: AFTER FIRST DAY size 13 3/8" | C25: 1100
A26: MKN-0014 | B26: All sizes, above 15,000 ft. per 100 ft. or fraction add | C26: 75
A27: MKN-0015 | B27: ADDITIONAL ZONE. Each ADDITIONAL ZONE on same run in well, any depth: | C27: 800
B28: (This change applies when tool is moved to another zone for any purpose.
B29: It does not include 'looking for casing leaks')
A30: MKN-0016 | B30: Unsuccessful run. | C30: 1100
A31: MKN-0017 | B31: Each Reset Packer For All Sizes | C31: 200
A34: RETRIEVABLE BRIDGE PLUG
A35: "RETRIEVABLE BRIDG PLUG (WHEN RUN SEPARATELY) PRICE IS DETERMINED BY SIZE AND DEPTHPACKER.SET. TIME OF JOB BEGINS WHEN TOOL STARTS IN WELL AND TIME END WHEN RECOVERED FROM WELL .FRIST-EIGHT (8) HOURS OR FRACTION"
A36: Item Code | B36: Description | C36: Price
A37: MKN-0018 | B37: Size thru 7" : first day | C37: 2200
A38: MKN-0019 | B38: Size thru 7" : after first day | C38: 850
A39: MKN-0020 | B39: Size thru 9 5/8" : first day | C39: 2900
A40: MKN-0021 | B40: Size thru 9 5/8" : after first day | C40: 950
A41: MKN-0022 | B41: Size 13 3/8" : first day | C41: 5000
A42: MKN-0023 | B42: Size 13 3/8" : after first day | C42: 1100
A43: MKN-0024 | B43: All sizes above 15,000 ft. per 100 ft. or fraction: add | C43: 75
A44: MKN-0025 | B44: ADDITIONAL TIME. Each additional consecutive 8-hour or fraction | C44: 1100
A45: MKN-0026 | B45: Frac sand (M.E.) 20–40 per pound | C45: 3.6
...
